I'm sorry, but an uncaught exception occurred.

While running game code:
  File "game/story/ch2_follow_thioran_escaperoom.rpy", line 36, in script
    Guard "Everything alright in there?"
Exception: Sayer 'Guard' is not defined.

-- Full Traceback ------------------------------------------------------------

Full traceback:
  File "game/story/ch2_follow_thioran_escaperoom.rpy", line 36, in script
    Guard "Everything alright in there?"
  File "C:\Users\kansa\Desktop\renpy-8.1.3-sdk\renpy\ast.py", line 2586, in execute
    Say.execute(self)
  File "C:\Users\kansa\Desktop\renpy-8.1.3-sdk\renpy\ast.py", line 583, in execute
    who = eval_who(self.who, self.who_fast)
  File "C:\Users\kansa\Desktop\renpy-8.1.3-sdk\renpy\ast.py", line 472, in eval_who
    raise Exception("Sayer '%s' is not defined." % who)
Exception: Sayer 'Guard' is not defined.

Windows-10-10.0.19045 AMD64
Ren'Py 8.3.6.25022803
HeartsDepthDEMO 2.5
Wed Oct 22 19:46:24 2025
