I'm sorry, but an uncaught exception occurred.

While running game code:
  File "game/script.rpy", line 865, in script
    Y "Come on, you can do a favor for an old friend, right?"
Exception: Sayer 'Y' is not defined.

-- Full Traceback ------------------------------------------------------------

Full traceback:
  File "game/script.rpy", line 865, in script
    Y "Come on, you can do a favor for an old friend, right?"
  File "C:\Users\kansa\Desktop\renpy-8.1.3-sdk\renpy\ast.py", line 2586, in execute
    Say.execute(self)
  File "C:\Users\kansa\Desktop\renpy-8.1.3-sdk\renpy\ast.py", line 583, in execute
    who = eval_who(self.who, self.who_fast)
  File "C:\Users\kansa\Desktop\renpy-8.1.3-sdk\renpy\ast.py", line 472, in eval_who
    raise Exception("Sayer '%s' is not defined." % who)
Exception: Sayer 'Y' is not defined.

Windows-10-10.0.19045 AMD64
Ren'Py 8.3.6.25022803
HeartsDepthDEMO 2.0.1
Mon Jun 16 19:26:45 2025
